Workbook

Sheet Break-Even
A1: Dropshipping break-even calculator
A2: Blue cells on yellow are inputs: edit only those. Everything else is a formula. Example values are placeholders, not research.
A4: INPUTS: per-order economics
A5: Retail price | B5: 45 | C5: Plan gate: $30-80
A6: Product cost (supplier) | B6: 12 | C6: Quote from US-warehouse supplier
A7: Shipping cost to customer | B7: 6 | C7: Supplier shipping fee for 1 unit
A8: Payment fee, percent of price | B8: 0.029 | C8: Typical card processor rate; check your processor
A9: Payment fee, fixed per order | B9: 0.3 | C9: Typical; check your processor
A10: Refund + chargeback reserve, percent of price | B10: 0.05 | C10: Plan assumption, not measured
A11: Other per-order cost (packaging, app fee) | B11: 0 | C11: Add per-order costs not listed above
A13: INPUTS: ad funnel
A14: Cost per click (CPC) | B14: 0.6 | C14: Assumption. Replace with real test data
A15: Click-to-purchase conversion rate | B15: 0.02 | C15: Assumption. Cold-traffic stores often see 1-3%
A16: Test ad budget | B16: 300 | C16: Plan cap: $300 ads
A17: Fixed costs (store, tools, sample) | B17: 100 | C17: Plan cap: $100
A19: OUTPUTS: unit economics
A20: Landed cost (product + shipping + other) | B20: =B6+B7+B11
A21: Gross margin per order | B21: =B5-B20
A22: Gross margin % | B22: =IF(B5>0,B21/B5,0) | C22: Plan gate: at least 50%
A23: Payment fees per order | B23: =B5*B8+B9
A24: Refund/chargeback reserve per order | B24: =B5*B10
A25: Contribution margin per order (M) | B25: =B21-B23-B24 | C25: =break-even cost per purchase
A26: Break-even ROAS | B26: =IF(B25>0,B5/B25,0) | C26: Revenue per ad $ needed to break even
A28: OUTPUTS: ads vs margin
A29: Expected cost per purchase (CPA = CPC / conversion) | B29: =IF(B15>0,B14/B15,0)
A30: Profit per order after ads | B30: =B25-B29
A31: Required conversion rate to break even | B31: =IF(B25>0,B14/B25,0) | C31: Plan gate: reject if above 4%
A32: Expected purchases from ad budget | B32: =IF(B29>0,B16/B29,0)
A33: Expected profit after ads, before fixed costs | B33: =B32*B30
A34: Expected profit after ads and fixed costs | B34: =B33-B17
A36: PLAN THRESHOLDS (from DROPSHIPPING_TEST_PLAN.md)
A37: Pass: CPA must be at or below 0.7 x M | B37: =0.7*B25
A38: Keep going: CPA at or below 1.5 x M (kill above, after 10+ purchases) | B38: =1.5*B25
A39: Zero-purchase kill: ad spend with no sales | B39: =150 | C39: Plan rule 2
A41: PRE-SPEND GATES
A42: Gross margin at least 50% | B42: =IF(B22>=0.5,"PASS","FAIL")
A43: Price between $30 and $80 | B43: =IF(AND(B5>=30,B5<=80),"PASS","FAIL")
A44: Required conversion at most 4% | B44: =IF(AND(B31>0,B31<=0.04),"PASS","FAIL")
A45: Contribution margin positive | B45: =IF(B25>0,"PASS","FAIL")
A46: Expected CPA at or below M | B46: =IF(B29<=B25,"PASS","FAIL")
...

Sheet Sensitivity
A1: Profit per order after ads: CPC vs conversion rate
A2: Profit per order = M - (CPC / conversion). M comes from Break-Even!B25. Green = profitable, red = losing.
A4: Contribution margin M | B4: ='Break-Even'!B25
A6: CPC (down) / conversion (across) | B6: 0.01 | C6: 0.015 | D6: 0.02 | E6: 0.025 | F6: 0.03 | G6: 0.04 | H6: 0.05
A7: 0.3 | B7: =IF(B$6>0,$B$4-$A7/B$6,0) | C7: =IF(C$6>0,$B$4-$A7/C$6,0) | D7: =IF(D$6>0,$B$4-$A7/D$6,0) | E7: =IF(E$6>0,$B$4-$A7/E$6,0) | F7: =IF(F$6>0,$B$4-$A7/F$6,0) | G7: =IF(G$6>0,$B$4-$A7/G$6,0) | H7: =IF(H$6>0,$B$4-$A7/H$6,0)
A8: 0.4 | B8: =IF(B$6>0,$B$4-$A8/B$6,0) | C8: =IF(C$6>0,$B$4-$A8/C$6,0) | D8: =IF(D$6>0,$B$4-$A8/D$6,0) | E8: =IF(E$6>0,$B$4-$A8/E$6,0) | F8: =IF(F$6>0,$B$4-$A8/F$6,0) | G8: =IF(G$6>0,$B$4-$A8/G$6,0) | H8: =IF(H$6>0,$B$4-$A8/H$6,0)
A9: 0.5 | B9: =IF(B$6>0,$B$4-$A9/B$6,0) | C9: =IF(C$6>0,$B$4-$A9/C$6,0) | D9: =IF(D$6>0,$B$4-$A9/D$6,0) | E9: =IF(E$6>0,$B$4-$A9/E$6,0) | F9: =IF(F$6>0,$B$4-$A9/F$6,0) | G9: =IF(G$6>0,$B$4-$A9/G$6,0) | H9: =IF(H$6>0,$B$4-$A9/H$6,0)
A10: 0.6 | B10: =IF(B$6>0,$B$4-$A10/B$6,0) | C10: =IF(C$6>0,$B$4-$A10/C$6,0) | D10: =IF(D$6>0,$B$4-$A10/D$6,0) | E10: =IF(E$6>0,$B$4-$A10/E$6,0) | F10: =IF(F$6>0,$B$4-$A10/F$6,0) | G10: =IF(G$6>0,$B$4-$A10/G$6,0) | H10: =IF(H$6>0,$B$4-$A10/H$6,0)
A11: 0.8 | B11: =IF(B$6>0,$B$4-$A11/B$6,0) | C11: =IF(C$6>0,$B$4-$A11/C$6,0) | D11: =IF(D$6>0,$B$4-$A11/D$6,0) | E11: =IF(E$6>0,$B$4-$A11/E$6,0) | F11: =IF(F$6>0,$B$4-$A11/F$6,0) | G11: =IF(G$6>0,$B$4-$A11/G$6,0) | H11: =IF(H$6>0,$B$4-$A11/H$6,0)
A12: 1 | B12: =IF(B$6>0,$B$4-$A12/B$6,0) | C12: =IF(C$6>0,$B$4-$A12/C$6,0) | D12: =IF(D$6>0,$B$4-$A12/D$6,0) | E12: =IF(E$6>0,$B$4-$A12/E$6,0) | F12: =IF(F$6>0,$B$4-$A12/F$6,0) | G12: =IF(G$6>0,$B$4-$A12/G$6,0) | H12: =IF(H$6>0,$B$4-$A12/H$6,0)
A13: 1.25 | B13: =IF(B$6>0,$B$4-$A13/B$6,0) | C13: =IF(C$6>0,$B$4-$A13/C$6,0) | D13: =IF(D$6>0,$B$4-$A13/D$6,0) | E13: =IF(E$6>0,$B$4-$A13/E$6,0) | F13: =IF(F$6>0,$B$4-$A13/F$6,0) | G13: =IF(G$6>0,$B$4-$A13/G$6,0) | H13: =IF(H$6>0,$B$4-$A13/H$6,0)
A14: 1.5 | B14: =IF(B$6>0,$B$4-$A14/B$6,0) | C14: =IF(C$6>0,$B$4-$A14/C$6,0) | D14: =IF(D$6>0,$B$4-$A14/D$6,0) | E14: =IF(E$6>0,$B$4-$A14/E$6,0) | F14: =IF(F$6>0,$B$4-$A14/F$6,0) | G14: =IF(G$6>0,$B$4-$A14/G$6,0) | H14: =IF(H$6>0,$B$4-$A14/H$6,0)
A17: Axis values (blue) are editable.

Sheet Test Log
A1: 28-day test log and kill-rule monitor
A2: Enter daily numbers in the blue/yellow columns only. Day 1 holds an example row: overwrite it.
D3: Kill rule | F3: Status
A4: Cash spent to date (ads + fixed costs) | B4: =B5+'Break-Even'!B17 | D4: 1. Cash spent at or above $400 | F4: =IF(B4>=400,"KILL","ok")
A5: Ad spend to date | B5: =SUM(B13:B40) | D5: 2. $150 ad spend with 0 purchases | F5: =IF(AND(B5>=150,B6=0),"KILL","ok")
A6: Purchases to date | B6: =SUM(F13:F40) | D6: 3. 10+ purchases and CPA > 1.5 x M | F6: =IF(AND(B6>=10,B7>1.5*'Break-Even'!$B$25),"KILL","ok")
A7: Blended CPA | B7: =IF(B6>0,B5/B6,0) | D7: 4. Refund rate above 10% | F7: =IF(B8>0.1,"KILL","ok")
A8: Refund rate (refunded orders / purchases) | B8: =IF(B6>0,SUM(J13:J40)/B6,0) | D8: Rule 5 (supplier stock-out / slow delivery), payment holds and ad-platform warnings are manual: note them below and stop.
A9: Contribution profit to date (purchases x M - ad spend) | B9: =B6*'Break-Even'!$B$25-B5 | D9: Rule 6: the test ends on day 28. Verdict thresholds come from DROPSHIPPING_TEST_PLAN.md.
A10: Day-28 verdict | B10: =IF(COUNTIF(F4:F7,"KILL")>0,"KILLED",IF(AND(B6>=15,B7<=0.7*'Break-Even'!$B$25,B9>0,B8<0.08),"PASS",IF(AND(B6>=8,B7<='Break-Even'!$B$25),"INCONCLUSIVE","FAIL / IN PROGRESS")))
A12: Day | B12: Ad spend ($) | C12: Impressions | D12: Clicks | E12: Add-to-cart | F12: Purchases | G12: Revenue ($) | H12: Product+ship cost ($) | I12: Payment fees ($) | J12: Refunded orders | K12: CPA ($) | L12: Notes
A13: 1 | B13: 20 | C13: 2500 | D13: 40 | E13: 3 | F13: 0 | G13: 0 | H13: 0 | I13: 0 | J13: 0 | K13: =IF(F13>0,B13/F13,0) | L13: Example row: replace
A14: 2 | K14: =IF(F14>0,B14/F14,0)
A15: 3 | K15: =IF(F15>0,B15/F15,0)
A16: 4 | K16: =IF(F16>0,B16/F16,0)
A17: 5 | K17: =IF(F17>0,B17/F17,0)
A18: 6 | K18: =IF(F18>0,B18/F18,0)
A19: 7 | K19: =IF(F19>0,B19/F19,0)
A20: 8 | K20: =IF(F20>0,B20/F20,0)
A21: 9 | K21: =IF(F21>0,B21/F21,0)
A22: 10 | K22: =IF(F22>0,B22/F22,0)
A23: 11 | K23: =IF(F23>0,B23/F23,0)
A24: 12 | K24: =IF(F24>0,B24/F24,0)
A25: 13 | K25: =IF(F25>0,B25/F25,0)
... A40: 28 | K40: =IF(F40>0,B40/F40,0)

Sheet Notes
A1: Assumptions and sources
A3: Source: DROPSHIPPING_TEST_PLAN.md in this repo (kill rules, thresholds, gates). Written before any data.
A4: Example inputs (price $45, product $12, shipping $6, CPC $0.60, conversion 2%) are placeholders chosen by the author, not measured or researched.
A5: Payment fee 2.9% + $0.30 is a common card-processor rate, not a quote. Check your processor.
A6: Refund/chargeback reserve of 5% is a plan assumption. Replace it with your actual rate once orders arrive.
A7: CPC and conversion are the biggest unknowns. Replace them with real test numbers after Phase 1.
A8: Benchmarks from the earlier web search (vendor blogs, not independent): net margins 5-20%, ad cost $8-15 per order.
A9: Taxes, shipping-tax rules and platform subscription fees are not modelled. Add them to 'Other per-order cost' or Fixed costs.
A10: Tab guide: Break-Even = inputs and gates. Sensitivity = profit grid. Test Log = daily log with kill-rule checks.
