Workbook

Sheet Summary
A1: Income scenarios: summary
A2: Estimates from my own assumptions, not forecasts. Replace the Assumptions with your real numbers as you learn them.
B4: Pessimistic | C4: Moderate | D4: Strong
A5: Total net, month 3 | B5: =Projection!J8 | C5: =Projection!J25 | D5: =Projection!J42
A6: Total net, month 6 | B6: =Projection!J11 | C6: =Projection!J28 | D6: =Projection!J45
A7: Total net, month 9 | B7: =Projection!J14 | C7: =Projection!J31 | D7: =Projection!J48
A8: Total net, month 12 | B8: =Projection!J17 | C8: =Projection!J34 | D8: =Projection!J51
A9: Cumulative net after 12 months | B9: =Projection!K17 | C9: =Projection!K34 | D9: =Projection!K51
A10: Email list size, month 12 | B10: =Projection!C17 | C10: =Projection!C34 | D10: =Projection!C51
A11: Net per hour worked, month 12 | B11: =IF(Assumptions!B33>0,B8/(Assumptions!B33*52/12),0) | C11: =IF(Assumptions!C33>0,C8/(Assumptions!C33*52/12),0) | D11: =IF(Assumptions!D33>0,D8/(Assumptions!D33*52/12),0)
A12: Months to reach $1,000 a month | B12: =IF(COUNT(Projection!L6:L17)=0,"not in 12 months",MIN(Projection!L6:L17)) | C12: =IF(COUNT(Projection!L23:L34)=0,"not in 12 months",MIN(Projection!L23:L34)) | D12: =IF(COUNT(Projection!L40:L51)=0,"not in 12 months",MIN(Projection!L40:L51))
A14: My rough judgment of likelihood (not a statistic)
A15: Pessimistic: roughly half or more of outcomes. Moderate: plausible with steady posting and real conversations. Strong: needs something to take off. $10,000 a month is not reached in any scenario here.
A17: Not modelled: taxes, platform changes, algorithm changes, time off, your hourly alternatives.

Sheet Assumptions
A1: Income scenarios: assumptions
A2: Blue on yellow = inputs (all are my guesses, not measured data). Everything else is a formula. Change a value and the other tabs update.
A4: SCENARIOS | B4: Pessimistic | C4: Moderate | D4: Strong | E4: Notes
A5: AUDIENCE
A6: New email subscribers per month | B6: 30 | C6: 100 | D6: 300 | E6: Biggest unknown. Depends on posting and community
A7: Monthly list churn (unsubscribes) | B7: 0.02 | C7: 0.02 | D7: 0.02 | E7: Assumption
A9: GUIDE
A10: Guide price | B10: 19 | C10: 19 | D10: 19 | E10: Price hypothesis; test it
A11: Platform fee, percent | B11: 0.05 | C11: 0.05 | D11: 0.05 | E11: Payhip free plan reported 5%; verify
A12: Payment fee, percent | B12: 0.029 | C12: 0.029 | D12: 0.029 | E12: Typical card rate; verify
A13: Payment fee, fixed per sale | B13: 0.3 | C13: 0.3 | D13: 0.3 | E13: Typical; verify
A14: Refund reserve, percent | B14: 0.05 | C14: 0.05 | D14: 0.05 | E14: Assumption
A15: Guide launch month (first sales) | B15: 4 | C15: 4 | D15: 4 | E15: Months after you start
A16: Guide buyers per 1,000 list members per month | B16: 10 | C16: 30 | D16: 50 | E16: Assumption: 1% / 3% / 5% of the list per month
A18: PAID 1-ON-1 SESSIONS (free chats earn nothing)
A19: First month you charge | B19: 5 | C19: 5 | D19: 4 | E19: Free-only mode: charge after about 5 free chats
A20: Paid sessions per month | B20: 1 | C20: 6 | D20: 12 | E20: Capped by your hours
A21: Session price | B21: 75 | C21: 100 | D21: 125 | E21: Price hypothesis; check the market
A22: Session fee, percent (card fees) | B22: 0.03 | C22: 0.03 | D22: 0.03 | E22: Assumption
A24: COHORT / GROUP COURSE
A25: First cohort month | B25: 0 | C25: 7 | D25: 7 | E25: 0 = no cohort in the first 12 months
A26: Second cohort month | B26: 0 | C26: 10 | D26: 10 | E26: 0 = none
A27: Students per cohort | B27: 0 | C27: 10 | D27: 25 | E27: Assumption
A28: Cohort price per student | B28: 149 | C28: 199 | D28: 249 | E28: Price hypothesis
A29: Cohort platform and card fees, percent | B29: 0.1 | C29: 0.1 | D29: 0.1 | E29: Assumption
A31: COSTS AND TIME
A32: Monthly costs (free-only mode = 0) | B32: 0 | C32: 0 | D32: 0 | E32: Add costs if you upgrade tools
A33: Hours per week you work on it | B33: 6 | C33: 6 | D33: 6 | E33: Plan: 5-8
A35: DERIVED
A36: Net per guide sale | B36: =B10*(1-B11-B12-B14)-B13 | C36: =C10*(1-C11-C12-C14)-C13 | D36: =D10*(1-D11-D12-D14)-D13

Sheet Projection
A1: Monthly projection (12 months)
A2: All formulas. Driven by the Assumptions tab.
A4: PESSIMISTIC
A5: Month | B5: New subs | C5: List size | D5: Guide sales | E5: Guide net $ | F5: Paid sessions | G5: Session net $ | H5: Cohort net $ | I5: Costs $ | J5: Total net $ | K5: Cumulative $ | L5: Month if net >= $1,000
A6: 1 | B6: =Assumptions!B$6 | C6: =B6 | D6: =IF(A6>=Assumptions!B$15,C6*Assumptions!B$16/1000,0) | E6: =D6*Assumptions!B$36 | F6: =IF(A6>=Assumptions!B$19,Assumptions!B$20,0) | G6: =F6*Assumptions!B$21*(1-Assumptions!B$22) | H6: =IF(OR(A6=Assumptions!B$25,A6=Assumptions!B$26),Assumptions!B$27*Assumptions!B$28*(1-Assumptions!B$29),0) | I6: =Assumptions!B$32 | J6: =E6+G6+H6-I6 | K6: =J6 | L6: =IF(J6>=1000,A6,"")
A7: 2 | B7: =Assumptions!B$6 | C7: =C6*(1-Assumptions!B$7)+B7 | D7: =IF(A7>=Assumptions!B$15,C7*Assumptions!B$16/1000,0) | E7: =D7*Assumptions!B$36 | F7: =IF(A7>=Assumptions!B$19,Assumptions!B$20,0) | G7: =F7*Assumptions!B$21*(1-Assumptions!B$22) | H7: =IF(OR(A7=Assumptions!B$25,A7=Assumptions!B$26),Assumptions!B$27*Assumptions!B$28*(1-Assumptions!B$29),0) | I7: =Assumptions!B$32 | J7: =E7+G7+H7-I7 | K7: =K6+J7 | L7: =IF(J7>=1000,A7,"")
A8: 3 | B8: =Assumptions!B$6 | C8: =C7*(1-Assumptions!B$7)+B8 | D8: =IF(A8>=Assumptions!B$15,C8*Assumptions!B$16/1000,0) | E8: =D8*Assumptions!B$36 | F8: =IF(A8>=Assumptions!B$19,Assumptions!B$20,0) | G8: =F8*Assumptions!B$21*(1-Assumptions!B$22) | H8: =IF(OR(A8=Assumptions!B$25,A8=Assumptions!B$26),Assumptions!B$27*Assumptions!B$28*(1-Assumptions!B$29),0) | I8: =Assumptions!B$32 | J8: =E8+G8+H8-I8 | K8: =K7+J8 | L8: =IF(J8>=1000,A8,"")
A9: 4 | B9: =Assumptions!B$6 | C9: =C8*(1-Assumptions!B$7)+B9 | D9: =IF(A9>=Assumptions!B$15,C9*Assumptions!B$16/1000,0) | E9: =D9*Assumptions!B$36 | F9: =IF(A9>=Assumptions!B$19,Assumptions!B$20,0) | G9: =F9*Assumptions!B$21*(1-Assumptions!B$22) | H9: =IF(OR(A9=Assumptions!B$25,A9=Assumptions!B$26),Assumptions!B$27*Assumptions!B$28*(1-Assumptions!B$29),0) | I9: =Assumptions!B$32 | J9: =E9+G9+H9-I9 | K9: =K8+J9 | L9: =IF(J9>=1000,A9,"")
A10: 5 | B10: =Assumptions!B$6 | C10: =C9*(1-Assumptions!B$7)+B10 | D10: =IF(A10>=Assumptions!B$15,C10*Assumptions!B$16/1000,0) | E10: =D10*Assumptions!B$36 | F10: =IF(A10>=Assumptions!B$19,Assumptions!B$20,0) | G10: =F10*Assumptions!B$21*(1-Assumptions!B$22) | H10: =IF(OR(A10=Assumptions!B$25,A10=Assumptions!B$26),Assumptions!B$27*Assumptions!B$28*(1-Assumptions!B$29),0) | I10: =Assumptions!B$32 | J10: =E10+G10+H10-I10 | K10: =K9+J10 | L10: =IF(J10>=1000,A10,"")
A11: 6 | B11: =Assumptions!B$6 | C11: =C10*(1-Assumptions!B$7)+B11 | D11: =IF(A11>=Assumptions!B$15,C11*Assumptions!B$16/1000,0) | E11: =D11*Assumptions!B$36 | F11: =IF(A11>=Assumptions!B$19,Assumptions!B$20,0) | G11: =F11*Assumptions!B$21*(1-Assumptions!B$22) | H11: =IF(OR(A11=Assumptions!B$25,A11=Assumptions!B$26),Assumptions!B$27*Assumptions!B$28*(1-Assumptions!B$29),0) | I11: =Assumptions!B$32 | J11: =E11+G11+H11-I11 | K11: =K10+J11 | L11: =IF(J11>=1000,A11,"")
A12: 7 | B12: =Assumptions!B$6 | C12: =C11*(1-Assumptions!B$7)+B12 | D12: =IF(A12>=Assumptions!B$15,C12*Assumptions!B$16/1000,0) | E12: =D12*Assumptions!B$36 | F12: =IF(A12>=Assumptions!B$19,Assumptions!B$20,0) | G12: =F12*Assumptions!B$21*(1-Assumptions!B$22) | H12: =IF(OR(A12=Assumptions!B$25,A12=Assumptions!B$26),Assumptions!B$27*Assumptions!B$28*(1-Assumptions!B$29),0) | I12: =Assumptions!B$32 | J12: =E12+G12+H12-I12 | K12: =K11+J12 | L12: =IF(J12>=1000,A12,"")
A13: 8 | B13: =Assumptions!B$6 | C13: =C12*(1-Assumptions!B$7)+B13 | D13: =IF(A13>=Assumptions!B$15,C13*Assumptions!B$16/1000,0) | E13: =D13*Assumptions!B$36 | F13: =IF(A13>=Assumptions!B$19,Assumptions!B$20,0) | G13: =F13*Assumptions!B$21*(1-Assumptions!B$22) | H13: =IF(OR(A13=Assumptions!B$25,A13=Assumptions!B$26),Assumptions!B$27*Assumptions!B$28*(1-Assumptions!B$29),0) | I13: =Assumptions!B$32 | J13: =E13+G13+H13-I13 | K13: =K12+J13 | L13: =IF(J13>=1000,A13,"")
A14: 9 | B14: =Assumptions!B$6 | C14: =C13*(1-Assumptions!B$7)+B14 | D14: =IF(A14>=Assumptions!B$15,C14*Assumptions!B$16/1000,0) | E14: =D14*Assumptions!B$36 | F14: =IF(A14>=Assumptions!B$19,Assumptions!B$20,0) | G14: =F14*Assumptions!B$21*(1-Assumptions!B$22) | H14: =IF(OR(A14=Assumptions!B$25,A14=Assumptions!B$26),Assumptions!B$27*Assumptions!B$28*(1-Assumptions!B$29),0) | I14: =Assumptions!B$32 | J14: =E14+G14+H14-I14 | K14: =K13+J14 | L14: =IF(J14>=1000,A14,"")
A15: 10 | B15: =Assumptions!B$6 | C15: =C14*(1-Assumptions!B$7)+B15 | D15: =IF(A15>=Assumptions!B$15,C15*Assumptions!B$16/1000,0) | E15: =D15*Assumptions!B$36 | F15: =IF(A15>=Assumptions!B$19,Assumptions!B$20,0) | G15: =F15*Assumptions!B$21*(1-Assumptions!B$22) | H15: =IF(OR(A15=Assumptions!B$25,A15=Assumptions!B$26),Assumptions!B$27*Assumptions!B$28*(1-Assumptions!B$29),0) | I15: =Assumptions!B$32 | J15: =E15+G15+H15-I15 | K15: =K14+J15 | L15: =IF(J15>=1000,A15,"")
A16: 11 | B16: =Assumptions!B$6 | C16: =C15*(1-Assumptions!B$7)+B16 | D16: =IF(A16>=Assumptions!B$15,C16*Assumptions!B$16/1000,0) | E16: =D16*Assumptions!B$36 | F16: =IF(A16>=Assumptions!B$19,Assumptions!B$20,0) | G16: =F16*Assumptions!B$21*(1-Assumptions!B$22) | H16: =IF(OR(A16=Assumptions!B$25,A16=Assumptions!B$26),Assumptions!B$27*Assumptions!B$28*(1-Assumptions!B$29),0) | I16: =Assumptions!B$32 | J16: =E16+G16+H16-I16 | K16: =K15+J16 | L16: =IF(J16>=1000,A16,"")
A17: 12 | B17: =Assumptions!B$6 | C17: =C16*(1-Assumptions!B$7)+B17 | D17: =IF(A17>=Assumptions!B$15,C17*Assumptions!B$16/1000,0) | E17: =D17*Assumptions!B$36 | F17: =IF(A17>=Assumptions!B$19,Assumptions!B$20,0) | G17: =F17*Assumptions!B$21*(1-Assumptions!B$22) | H17: =IF(OR(A17=Assumptions!B$25,A17=Assumptions!B$26),Assumptions!B$27*Assumptions!B$28*(1-Assumptions!B$29),0) | I17: =Assumptions!B$32 | J17: =E17+G17+H17-I17 | K17: =K16+J17 | L17: =IF(J17>=1000,A17,"")
A21: MODERATE
A22: Month | B22: New subs | C22: List size | D22: Guide sales | E22: Guide net $ | F22: Paid sessions | G22: Session net $ | H22: Cohort net $ | I22: Costs $ | J22: Total net $ | K22: Cumulative $ | L22: Month if net >= $1,000
A23: 1 | B23: =Assumptions!C$6 | C23: =B23 | D23: =IF(A23>=Assumptions!C$15,C23*Assumptions!C$16/1000,0) | E23: =D23*Assumptions!C$36 | F23: =IF(A23>=Assumptions!C$19,Assumptions!C$20,0) | G23: =F23*Assumptions!C$21*(1-Assumptions!C$22) | H23: =IF(OR(A23=Assumptions!C$25,A23=Assumptions!C$26),Assumptions!C$27*Assumptions!C$28*(1-Assumptions!C$29),0) | I23: =Assumptions!C$32 | J23: =E23+G23+H23-I23 | K23: =J23 | L23: =IF(J23>=1000,A23,"")
A24: 2 | B24: =Assumptions!C$6 | C24: =C23*(1-Assumptions!C$7)+B24 | D24: =IF(A24>=Assumptions!C$15,C24*Assumptions!C$16/1000,0) | E24: =D24*Assumptions!C$36 | F24: =IF(A24>=Assumptions!C$19,Assumptions!C$20,0) | G24: =F24*Assumptions!C$21*(1-Assumptions!C$22) | H24: =IF(OR(A24=Assumptions!C$25,A24=Assumptions!C$26),Assumptions!C$27*Assumptions!C$28*(1-Assumptions!C$29),0) | I24: =Assumptions!C$32 | J24: =E24+G24+H24-I24 | K24: =K23+J24 | L24: =IF(J24>=1000,A24,"")
A25: 3 | B25: =Assumptions!C$6 | C25: =C24*(1-Assumptions!C$7)+B25 | D25: =IF(A25>=Assumptions!C$15,C25*Assumptions!C$16/1000,0) | E25: =D25*Assumptions!C$36 | F25: =IF(A25>=Assumptions!C$19,Assumptions!C$20,0) | G25: =F25*Assumptions!C$21*(1-Assumptions!C$22) | H25: =IF(OR(A25=Assumptions!C$25,A25=Assumptions!C$26),Assumptions!C$27*Assumptions!C$28*(1-Assumptions!C$29),0) | I25: =Assumptions!C$32 | J25: =E25+G25+H25-I25 | K25: =K24+J25 | L25: =IF(J25>=1000,A25,"")
A26: 4 | B26: =Assumptions!C$6 | C26: =C25*(1-Assumptions!C$7)+B26 | D26: =IF(A26>=Assumptions!C$15,C26*Assumptions!C$16/1000,0) | E26: =D26*Assumptions!C$36 | F26: =IF(A26>=Assumptions!C$19,Assumptions!C$20,0) | G26: =F26*Assumptions!C$21*(1-Assumptions!C$22) | H26: =IF(OR(A26=Assumptions!C$25,A26=Assumptions!C$26),Assumptions!C$27*Assumptions!C$28*(1-Assumptions!C$29),0) | I26: =Assumptions!C$32 | J26: =E26+G26+H26-I26 | K26: =K25+J26 | L26: =IF(J26>=1000,A26,"")
A27: 5 | B27: =Assumptions!C$6 | C27: =C26*(1-Assumptions!C$7)+B27 | D27: =IF(A27>=Assumptions!C$15,C27*Assumptions!C$16/1000,0) | E27: =D27*Assumptions!C$36 | F27: =IF(A27>=Assumptions!C$19,Assumptions!C$20,0) | G27: =F27*Assumptions!C$21*(1-Assumptions!C$22) | H27: =IF(OR(A27=Assumptions!C$25,A27=Assumptions!C$26),Assumptions!C$27*Assumptions!C$28*(1-Assumptions!C$29),0) | I27: =Assumptions!C$32 | J27: =E27+G27+H27-I27 | K27: =K26+J27 | L27: =IF(J27>=1000,A27,"")
A28: 6 | B28: =Assumptions!C$6 | C28: =C27*(1-Assumptions!C$7)+B28 | D28: =IF(A28>=Assumptions!C$15,C28*Assumptions!C$16/1000,0) | E28: =D28*Assumptions!C$36 | F28: =IF(A28>=Assumptions!C$19,Assumptions!C$20,0) | G28: =F28*Assumptions!C$21*(1-Assumptions!C$22) | H28: =IF(OR(A28=Assumptions!C$25,A28=Assumptions!C$26),Assumptions!C$27*Assumptions!C$28*(1-Assumptions!C$29),0) | I28: =Assumptions!C$32 | J28: =E28+G28+H28-I28 | K28: =K27+J28 | L28: =IF(J28>=1000,A28,"")
A29: 7 | B29: =Assumptions!C$6 | C29: =C28*(1-Assumptions!C$7)+B29 | D29: =IF(A29>=Assumptions!C$15,C29*Assumptions!C$16/1000,0) | E29: =D29*Assumptions!C$36 | F29: =IF(A29>=Assumptions!C$19,Assumptions!C$20,0) | G29: =F29*Assumptions!C$21*(1-Assumptions!C$22) | H29: =IF(OR(A29=Assumptions!C$25,A29=Assumptions!C$26),Assumptions!C$27*Assumptions!C$28*(1-Assumptions!C$29),0) | I29: =Assumptions!C$32 | J29: =E29+G29+H29-I29 | K29: =K28+J29 | L29: =IF(J29>=1000,A29,"")
A30: 8 | B30: =Assumptions!C$6 | C30: =C29*(1-Assumptions!C$7)+B30 | D30: =IF(A30>=Assumptions!C$15,C30*Assumptions!C$16/1000,0) | E30: =D30*Assumptions!C$36 | F30: =IF(A30>=Assumptions!C$19,Assumptions!C$20,0) | G30: =F30*Assumptions!C$21*(1-Assumptions!C$22) | H30: =IF(OR(A30=Assumptions!C$25,A30=Assumptions!C$26),Assumptions!C$27*Assumptions!C$28*(1-Assumptions!C$29),0) | I30: =Assumptions!C$32 | J30: =E30+G30+H30-I30 | K30: =K29+J30 | L30: =IF(J30>=1000,A30,"")
A31: 9 | B31: =Assumptions!C$6 | C31: =C30*(1-Assumptions!C$7)+B31 | D31: =IF(A31>=Assumptions!C$15,C31*Assumptions!C$16/1000,0) | E31: =D31*Assumptions!C$36 | F31: =IF(A31>=Assumptions!C$19,Assumptions!C$20,0) | G31: =F31*Assumptions!C$21*(1-Assumptions!C$22) | H31: =IF(OR(A31=Assumptions!C$25,A31=Assumptions!C$26),Assumptions!C$27*Assumptions!C$28*(1-Assumptions!C$29),0) | I31: =Assumptions!C$32 | J31: =E31+G31+H31-I31 | K31: =K30+J31 | L31: =IF(J31>=1000,A31,"")
A32: 10 | B32: =Assumptions!C$6 | C32: =C31*(1-Assumptions!C$7)+B32 | D32: =IF(A32>=Assumptions!C$15,C32*Assumptions!C$16/1000,0) | E32: =D32*Assumptions!C$36 | F32: =IF(A32>=Assumptions!C$19,Assumptions!C$20,0) | G32: =F32*Assumptions!C$21*(1-Assumptions!C$22) | H32: =IF(OR(A32=Assumptions!C$25,A32=Assumptions!C$26),Assumptions!C$27*Assumptions!C$28*(1-Assumptions!C$29),0) | I32: =Assumptions!C$32 | J32: =E32+G32+H32-I32 | K32: =K31+J32 | L32: =IF(J32>=1000,A32,"")
A33: 11 | B33: =Assumptions!C$6 | C33: =C32*(1-Assumptions!C$7)+B33 | D33: =IF(A33>=Assumptions!C$15,C33*Assumptions!C$16/1000,0) | E33: =D33*Assumptions!C$36 | F33: =IF(A33>=Assumptions!C$19,Assumptions!C$20,0) | G33: =F33*Assumptions!C$21*(1-Assumptions!C$22) | H33: =IF(OR(A33=Assumptions!C$25,A33=Assumptions!C$26),Assumptions!C$27*Assumptions!C$28*(1-Assumptions!C$29),0) | I33: =Assumptions!C$32 | J33: =E33+G33+H33-I33 | K33: =K32+J33 | L33: =IF(J33>=1000,A33,"")
A34: 12 | B34: =Assumptions!C$6 | C34: =C33*(1-Assumptions!C$7)+B34 | D34: =IF(A34>=Assumptions!C$15,C34*Assumptions!C$16/1000,0) | E34: =D34*Assumptions!C$36 | F34: =IF(A34>=Assumptions!C$19,Assumptions!C$20,0) | G34: =F34*Assumptions!C$21*(1-Assumptions!C$22) | H34: =IF(OR(A34=Assumptions!C$25,A34=Assumptions!C$26),Assumptions!C$27*Assumptions!C$28*(1-Assumptions!C$29),0) | I34: =Assumptions!C$32 | J34: =E34+G34+H34-I34 | K34: =K33+J34 | L34: =IF(J34>=1000,A34,"")
A38: STRONG
A39: Month | B39: New subs | C39: List size | D39: Guide sales | E39: Guide net $ | F39: Paid sessions | G39: Session net $ | H39: Cohort net $ | I39: Costs $ | J39: Total net $ | K39: Cumulative $ | L39: Month if net >= $1,000
A40: 1 | B40: =Assumptions!D$6 | C40: =B40 | D40: =IF(A40>=Assumptions!D$15,C40*Assumptions!D$16/1000,0) | E40: =D40*Assumptions!D$36 | F40: =IF(A40>=Assumptions!D$19,Assumptions!D$20,0) | G40: =F40*Assumptions!D$21*(1-Assumptions!D$22) | H40: =IF(OR(A40=Assumptions!D$25,A40=Assumptions!D$26),Assumptions!D$27*Assumptions!D$28*(1-Assumptions!D$29),0) | I40: =Assumptions!D$32 | J40: =E40+G40+H40-I40 | K40: =J40 | L40: =IF(J40>=1000,A40,"")
A41: 2 | B41: =Assumptions!D$6 | C41: =C40*(1-Assumptions!D$7)+B41 | D41: =IF(A41>=Assumptions!D$15,C41*Assumptions!D$16/1000,0) | E41: =D41*Assumptions!D$36 | F41: =IF(A41>=Assumptions!D$19,Assumptions!D$20,0) | G41: =F41*Assumptions!D$21*(1-Assumptions!D$22) | H41: =IF(OR(A41=Assumptions!D$25,A41=Assumptions!D$26),Assumptions!D$27*Assumptions!D$28*(1-Assumptions!D$29),0) | I41: =Assumptions!D$32 | J41: =E41+G41+H41-I41 | K41: =K40+J41 | L41: =IF(J41>=1000,A41,"")
A42: 3 | B42: =Assumptions!D$6 | C42: =C41*(1-Assumptions!D$7)+B42 | D42: =IF(A42>=Assumptions!D$15,C42*Assumptions!D$16/1000,0) | E42: =D42*Assumptions!D$36 | F42: =IF(A42>=Assumptions!D$19,Assumptions!D$20,0) | G42: =F42*Assumptions!D$21*(1-Assumptions!D$22) | H42: =IF(OR(A42=Assumptions!D$25,A42=Assumptions!D$26),Assumptions!D$27*Assumptions!D$28*(1-Assumptions!D$29),0) | I42: =Assumptions!D$32 | J42: =E42+G42+H42-I42 | K42: =K41+J42 | L42: =IF(J42>=1000,A42,"")
A43: 4 | B43: =Assumptions!D$6 | C43: =C42*(1-Assumptions!D$7)+B43 | D43: =IF(A43>=Assumptions!D$15,C43*Assumptions!D$16/1000,0) | E43: =D43*Assumptions!D$36 | F43: =IF(A43>=Assumptions!D$19,Assumptions!D$20,0) | G43: =F43*Assumptions!D$21*(1-Assumptions!D$22) | H43: =IF(OR(A43=Assumptions!D$25,A43=Assumptions!D$26),Assumptions!D$27*Assumptions!D$28*(1-Assumptions!D$29),0) | I43: =Assumptions!D$32 | J43: =E43+G43+H43-I43 | K43: =K42+J43 | L43: =IF(J43>=1000,A43,"")
A44: 5 | B44: =Assumptions!D$6 | C44: =C43*(1-Assumptions!D$7)+B44 | D44: =IF(A44>=Assumptions!D$15,C44*Assumptions!D$16/1000,0) | E44: =D44*Assumptions!D$36 | F44: =IF(A44>=Assumptions!D$19,Assumptions!D$20,0) | G44: =F44*Assumptions!D$21*(1-Assumptions!D$22) | H44: =IF(OR(A44=Assumptions!D$25,A44=Assumptions!D$26),Assumptions!D$27*Assumptions!D$28*(1-Assumptions!D$29),0) | I44: =Assumptions!D$32 | J44: =E44+G44+H44-I44 | K44: =K43+J44 | L44: =IF(J44>=1000,A44,"")
A45: 6 | B45: =Assumptions!D$6 | C45: =C44*(1-Assumptions!D$7)+B45 | D45: =IF(A45>=Assumptions!D$15,C45*Assumptions!D$16/1000,0) | E45: =D45*Assumptions!D$36 | F45: =IF(A45>=Assumptions!D$19,Assumptions!D$20,0) | G45: =F45*Assumptions!D$21*(1-Assumptions!D$22) | H45: =IF(OR(A45=Assumptions!D$25,A45=Assumptions!D$26),Assumptions!D$27*Assumptions!D$28*(1-Assumptions!D$29),0) | I45: =Assumptions!D$32 | J45: =E45+G45+H45-I45 | K45: =K44+J45 | L45: =IF(J45>=1000,A45,"")
A46: 7 | B46: =Assumptions!D$6 | C46: =C45*(1-Assumptions!D$7)+B46 | D46: =IF(A46>=Assumptions!D$15,C46*Assumptions!D$16/1000,0) | E46: =D46*Assumptions!D$36 | F46: =IF(A46>=Assumptions!D$19,Assumptions!D$20,0) | G46: =F46*Assumptions!D$21*(1-Assumptions!D$22) | H46: =IF(OR(A46=Assumptions!D$25,A46=Assumptions!D$26),Assumptions!D$27*Assumptions!D$28*(1-Assumptions!D$29),0) | I46: =Assumptions!D$32 | J46: =E46+G46+H46-I46 | K46: =K45+J46 | L46: =IF(J46>=1000,A46,"")
A47: 8 | B47: =Assumptions!D$6 | C47: =C46*(1-Assumptions!D$7)+B47 | D47: =IF(A47>=Assumptions!D$15,C47*Assumptions!D$16/1000,0) | E47: =D47*Assumptions!D$36 | F47: =IF(A47>=Assumptions!D$19,Assumptions!D$20,0) | G47: =F47*Assumptions!D$21*(1-Assumptions!D$22) | H47: =IF(OR(A47=Assumptions!D$25,A47=Assumptions!D$26),Assumptions!D$27*Assumptions!D$28*(1-Assumptions!D$29),0) | I47: =Assumptions!D$32 | J47: =E47+G47+H47-I47 | K47: =K46+J47 | L47: =IF(J47>=1000,A47,"")
...

Sheet Notes
A1: Notes and sources
A3: Every input is an assumption by the author of this model, chosen to match the earlier rough range (under $500 a month for 6 months is most likely). None is measured.
A4: Fee numbers (Payhip 5%, card 2.9% + $0.30) come from third-party sources and need checking on the vendors' own pages.
A5: Prices ($19 guide, $75-125 sessions, $149-249 cohort) are hypotheses to test with real families.
A6: Free chats are assumed to earn nothing; the model charges only from the 'first month you charge'.
A7: No data on conversion for homeschool products was found; 1-5% of the list buying per month is a guess.
A8: To use: change values on Assumptions (blue on yellow). Summary and Projection update.
A9: Not financial advice.
